Workbook

Sheet Dashboard
B1: Factory Energy Analyser
B2: Energy Performance, Renewable Contribution & Savings Opportunities
B3: Period: 01-Apr-2025 to 31-Mar-2026
B5: TOTAL ENERGY | D5: ENERGY INTENSITY | F5: SOLAR SHARE | H5: PRODUCTION DAYS | J5: NON-PRODUCTION ENERGY | L5: PEAK DEMAND
B6: ='KPI Summary'!B4 -> 4489639 | D6: ='KPI Summary'!B12 -> 7.5467028 | F6: ='KPI Summary'!B7 -> 0.10574748 | H6: ='KPI Summary'!B9 -> 313 | J6: ='KPI Summary'!B13 -> 218009 | L6: ='KPI Summary'!B15 -> 520
B7: ="Grid "&TEXT('KPI Summary'!B5,"#,##0")&" + Solar "&TEXT('KPI Summary'!B6,"#,##0") -> Grid 40,14,871 + Solar 4,74,768 | D7: Production days only | F7: Solar ÷ total energy | H7: ="of "&'KPI Summary'!B17&" days · "&'KPI Summary'!B10&" non-production" -> of 365 days · 52 non-production | J7: =TEXT('KPI Summary'!B14,"0.0%")&" of total energy" -> 4.9% of total energy | L7: Maximum daily peak
B9: Monthly Energy — Grid and Solar (kWh) | H9: Production-Day Energy Intensity (kWh per unit)
B27: Solar Share of Total Energy (%) | H27: Temperature vs Energy — Production Days
B45: Solar share = monthly solar kWh ÷ monthly total kWh (grid + solar). Annual share is calculated from annual totals. | H45: ="Multiple regression temperature coefficient: ~"&TEXT('Analysis Summary'!B15,"0.0")&" kWh/°C, controlling for units produced (95% CI "&TEXT('Analysis Summary'!B21,"0.0")&"–"&TEXT('Analysis Summary'!B22,"0.0")&"; R² "&TEXT('Analysis Summary'!B23,"0.000")&"). Association ≠ causation. Dashed line = simple temperature-only fit (R² "&TEXT('Analysis Summary'!B24,"0.00")&")." -> Multiple regression temperature coefficient: ~39.8 kWh/°C, controlling for units produced (95% CI 28.6–50.9; R² 0.765). Association ≠ causation. Dashed line = simple temperature-only fit (R² 0.07).
B48: Potentially Wasteful Days — Statistical Screen | H48: Business Insights
B49: POTENTIALLY WASTEFUL DAYS | D49: THRESHOLD · 95th PERCENTILE, NON-PRODUCTION DAYS | H49: ="• Production-day energy intensity is "&TEXT('KPI Summary'!B12,"0.00")&" kWh/unit ("&TEXT('KPI Summary'!B11,"#,##0")&" kWh across "&TEXT('KPI Summary'!B8,"#,##0")&" units)." -> • Production-day energy intensity is 7.55 kWh/unit (42,71,630 kWh across 5,66,026 units).
B50: ='Analysis Summary'!B7 -> 3 | D50: ='Analysis Summary'!B5 -> 4687.7
B51: Date | D51: Day | E51: Total energy | G51: Above thresh. | H51: ="• Solar supplied "&TEXT('KPI Summary'!B7,"0.00%")&" of annual energy; monthly share ranged from "&TEXT('KPI Summary'!B20,"0.0%")&" to "&TEXT('KPI Summary'!B21,"0.0%")&"." -> • Solar supplied 10.57% of annual energy; monthly share ranged from 5.2% to 13.8%.
B52: ='Wasteful Days'!B9 -> 45788 | D52: ='Wasteful Days'!C9 -> Sunday | E52: ='Wasteful Days'!D9 -> 4917 | G52: ='Wasteful Days'!J9 -> 229.3
B53: ='Wasteful Days'!B10 -> 45795 | D53: ='Wasteful Days'!C10 -> Sunday | E53: ='Wasteful Days'!D10 -> 4790 | G53: ='Wasteful Days'!J10 -> 102.3 | H53: ="• "&TEXT('KPI Summary'!B13,"#,##0")&" kWh ("&TEXT('KPI Summary'!B14,"0.0%")&" of total) was consumed across "&'KPI Summary'!B10&" non-production days." -> • 2,18,009 kWh (4.9% of total) was consumed across 52 non-production days.
B54: ='Wasteful Days'!B11 -> 45830 | D54: ='Wasteful Days'!C11 -> Sunday | E54: ='Wasteful Days'!D11 -> 5179 | G54: ='Wasteful Days'!J11 -> 491.3
H55: ="• "&'Analysis Summary'!B7&" non-production days exceeded the 95th-percentile screening threshold of "&TEXT('Analysis Summary'!B5,"#,##0.0")&" kWh — flagged for review, not confirmed waste." -> • 3 non-production days exceeded the 95th-percentile screening threshold of 4,687.7 kWh — flagged for review, not confirmed waste.
B56: Statistical screening of non-production days; flag does not confirm operational waste.
H57: ="• Temperature has a positive association with energy use after controlling for production volume (~"&TEXT('Analysis Summary'!B15,"0.0")&" kWh/°C)." -> • Temperature has a positive association with energy use after controlling for production volume (~39.8 kWh/°C).
B60: Illustrative Savings Scenarios | H60: Management Action Plan — 30 / 60 / 90 Days
B61: Initiative | E61: Est. kWh opportunity | G61: Illustrative ₹ impact | H61: 30 DAYS | I61: Investigate the three statistically flagged non-production days and establish shutdown/standby checks.
B62: ='Savings Table'!B7 -> Non-production shutdown / standby reduction | E62: ='Savings Table'!C7 -> 130805.4 | G62: ='Savings Table'!D7 -> 1046443.2
B63: ='Savings Table'!B8 -> Production efficiency improvement | E63: ='Savings Table'!C8 -> 128148.9 | G63: ='Savings Table'!D8 -> 1025191.2 | H63: 60 DAYS | I63: Track production-day energy intensity and investigate high-intensity periods.
B64: ='Savings Table'!B9 -> Solar generation expansion | E64: ='Savings Table'!C9 -> 94953.6 | G64: ='Savings Table'!D9 -> 759628.8
B65: ='Savings Table'!B10 -> Breakdown-linked controls | E65: ='Savings Table'!C10 -> 42716.3 | G65: ='Savings Table'!D10 -> 341730.4 | H65: 90 DAYS | I65: Evaluate solar expansion and cooling/HVAC optimisation opportunities.
B66: ='Savings Table'!B11 -> Cooling / HVAC optimisation | E66: ='Savings Table'!C11 -> 7789 | G66: ='Savings Table'!D11 -> 62312
B67: Estimates use ₹8/kWh and require technical, financial and overlap validation. Illustrative scenarios — not guaranteed and not additive. | H67: Actions are recommendations for management review; owners and targets to be agreed.
B70: ="Source: Daily Energy sheet (365 days, synthetic data). Methods and checks: Analysis Summary, QA Checks — status: "&'QA Checks'!D2 -> Source: Daily Energy sheet (365 days, synthetic data). Methods and checks: Analysis Summary, QA Checks — status: ALL 50 CHECKS PASS

Sheet Task Brief
A1: T15 Factory energy analyser
A2: Mini project | 30 marks | Build something with free LLM tools
A4: Task ID | B4: T15
A5: Task | B5: Factory energy analyser
A6: Theme | B6: No-code apps & dashboards
A7: Suggested free tools | B7: Gemini Canvas, ChatGPT Canvas or Claude (free) to generate the app; Excel / Google Sheets to verify numbers
A8: What students do | B8: 1. Build a dashboard of energy use per unit produced, solar share, and temperature effect. 2. Find wasteful days (high kWh on non-production days). 3. Ask the LLM for 5 savings ideas and estimate each one's rupee impact. 4. Present a 1-page energy plan.
A9: Deliverables | B9: Dashboard; savings table; energy plan; AI-use log
A10: Dataset in this file | B10: 365 days of grid and solar kWh, production and temperature - 'Daily Energy' sheet: 365 rows x 10 columns
A11: About the data | B11: All data is synthetic and created for teaching; companies, people and figures are fictional. Treat it as if it were real business data. If a 'Gold Labels (evaluation)' sheet is present, do NOT give it to the AI tool - use it only at the end to measure your accuracy.
A12: Team size | B12: Individual (or pairs if your faculty allows)
A13: Responsible AI rules | B13: Use only free tools; never paste real personal or confidential data into public AI tools; verify every number the AI gives you; disclose AI-generated content.
A14: Submission | B14: 1) Build link / file / screen recording 2) This workbook with your outputs added as new sheets 3) Completed 'AI Use Log' sheet (minimum 15 entries) 4) 3-5 page report with recommendation and reflection
A16: Evaluation rubric (30 marks)
A17: Criterion | B17: What is assessed | C17: Marks | D17: Excellent | E17: Good | F17: Fair | G17: Poor
A18: 1. Working build | B18: Tool / bot / app / automation works end to end on the provided data; link, file or screen recording submitted | C18: 8 | D18: Runs fully (7-8) | E18: Minor gaps (5-6) | F18: Partly working (3-4) | G18: Not working (0-2)
A19: 2. Correctness and verification | B19: Outputs checked against the data or gold labels; accuracy measured; errors found and fixed | C19: 7 | D19: Systematic checks with numbers (6-7) | E19: Some checks (4-5) | F19: Few checks (2-3) | G19: None (0-1)
A20: 3. Prompting and iteration | B20: Clear, structured prompts; at least 3 documented improvement rounds with reasons | C20: 5 | D20: Strong iteration (5) | E20: Some iteration (3-4) | F20: Mostly one-shot (2) | G20: No log (0-1)
A21: 4. Business insight and recommendation | B21: Specific, data-backed recommendation for the stated manager or customer | C21: 6 | D21: Actionable and quantified (6) | E21: Sound but generic (4-5) | F21: Descriptive only (2-3) | G21: Missing (0-1)
A22: 5. Documentation and reflection | B22: Complete AI-use log, limitations, responsible-AI notes and personal reflection | C22: 4 | D22: Complete and honest (4) | E22: Mostly complete (3) | F22: Thin (2) | G22: Missing (0-1)
A23: Total | C23: =SUM(C18:C22) -> 30

Sheet Daily Energy
A1: date | B1: day | C1: production_day | D1: units_produced | E1: avg_temp_c | F1: grid_kwh | G1: solar_kwh | H1: co2_tonnes_est | I1: peak_demand_kw | J1: machine_breakdowns
A2: 45748 | B2: Tuesday | C2: Yes | D2: 1672 | E2: 22.9 | F2: 11285 | G2: 1824 | H2: 8.13 | I2: 384 | J2: 1
A3: 45749 | B3: Wednesday | C3: Yes | D3: 1476 | E3: 25.9 | F3: 9783 | G3: 1470 | H3: 7.04 | I3: 416 | J3: 0
A4: 45750 | B4: Thursday | C4: Yes | D4: 1705 | E4: 25.2 | F4: 11177 | G4: 1940 | H4: 8.05 | I4: 476 | J4: 0
A5: 45751 | B5: Friday | C5: Yes | D5: 1902 | E5: 25 | F5: 12217 | G5: 2026 | H5: 8.8 | I5: 409 | J5: 1
A6: 45752 | B6: Saturday | C6: Yes | D6: 1848 | E6: 25.9 | F6: 12005 | G6: 1641 | H6: 8.64 | I6: 470 | J6: 2
A7: 45753 | B7: Sunday | C7: No | D7: 0 | E7: 24.3 | F7: 2486 | G7: 1577 | H7: 1.79 | I7: 519 | J7: 0
A8: 45754 | B8: Monday | C8: Yes | D8: 1705 | E8: 28.6 | F8: 11877 | G8: 1494 | H8: 8.55 | I8: 493 | J8: 1
A9: 45755 | B9: Tuesday | C9: Yes | D9: 1846 | E9: 26.7 | F9: 12109 | G9: 1929 | H9: 8.72 | I9: 406 | J9: 2
A10: 45756 | B10: Wednesday | C10: Yes | D10: 1991 | E10: 26.5 | F10: 12843 | G10: 1714 | H10: 9.25 | I10: 458 | J10: 2
A11: 45757 | B11: Thursday | C11: Yes | D11: 1529 | E11: 26.4 | F11: 10330 | G11: 1699 | H11: 7.44 | I11: 475 | J11: 2
A12: 45758 | B12: Friday | C12: Yes | D12: 1828 | E12: 26.8 | F12: 12148 | G12: 2077 | H12: 8.75 | I12: 513 | J12: 0
A13: 45759 | B13: Saturday | C13: Yes | D13: 1710 | E13: 24 | F13: 11688 | G13: 1507 | H13: 8.42 | I13: 506 | J13: 2
... A366: 46112 | B366: Tuesday | C366: Yes | D366: 1853 | E366: 23.7 | F366: 12752 | G366: 1740 | H366: 9.18 | I366: 415 | J366: 0

Sheet Data Dictionary
A1: sheet | B1: column | C1: data_type | D1: example_value | E1: non_empty_values | F1: distinct_values
A2: Daily Energy | B2: date | C2: Date/time | D2: 2025-04-01 | E2: 365 | F2: 365
A3: Daily Energy | B3: day | C3: Text | D3: Tuesday | E3: 365 | F3: 7
A4: Daily Energy | B4: production_day | C4: Text | D4: Yes | E4: 365 | F4: 2
A5: Daily Energy | B5: units_produced | C5: Whole number | D5: 1672 | E5: 365 | F5: 233
A6: Daily Energy | B6: avg_temp_c | C6: Decimal number | D6: 22.9 | E6: 365 | F6: 154
A7: Daily Energy | B7: grid_kwh | C7: Decimal number | D7: 11285.0 | E7: 365 | F7: 350
A8: Daily Energy | B8: solar_kwh | C8: Decimal number | D8: 1824.0 | E8: 365 | F8: 327
A9: Daily Energy | B9: co2_tonnes_est | C9: Decimal number | D9: 8.13 | E9: 365 | F9: 228
A10: Daily Energy | B10: peak_demand_kw | C10: Decimal number | D10: 384.0 | E10: 365 | F10: 130
A11: Daily Energy | B11: machine_breakdowns | C11: Whole number | D11: 1 | E11: 365 | F11: 3

Sheet Data Validation
A1: Data Validation
A2: Integrity checks on the Daily Energy sheet (raw data unchanged)
A3: Check | B3: Result | C3: Expected | D3: Status | E3: Note
A4: Record count | B4: =COUNTA('Daily Energy'!$A$2:$A$366) -> 365 | C4: 365 | D4: =IF(B4=C4,"PASS","FAIL") -> PASS
A5: Missing values (all 10 columns) | B5: =COUNTBLANK('Daily Energy'!$A$2:$J$366) -> 0 | C5: 0 | D5: =IF(B5=C5,"PASS","FAIL") -> PASS
A6: Duplicate dates | B6: =SUMPRODUCT((COUNTIF('Daily Energy'!$A$2:$A$366,'Daily Energy'!$A$2:$A$366)>1)*1) -> 0 | C6: 0 | D6: =IF(B6=C6,"PASS","FAIL") -> PASS | E6: Rows sharing a date with another row
A7: First date | B7: =MIN('Daily Energy'!$A$2:$A$366) -> 45748 | C7: 45748 | D7: =IF(B7=C7,"PASS","FAIL") -> PASS
A8: Last date | B8: =MAX('Daily Energy'!$A$2:$A$366) -> 46112 | C8: 46112 | D8: =IF(B8=C8,"PASS","FAIL") -> PASS
A9: Date continuity — days with gap ≠ 1 day | B9: =SUMPRODUCT(--('Daily Energy'!$A$3:$A$366-'Daily Energy'!$A$2:$A$365<>1)) -> 0 | C9: 0 | D9: =IF(B9=C9,"PASS","FAIL") -> PASS | E9: Consecutive-date differences
A10: Date continuity — span (last − first + 1) | B10: =B8-B7+1 -> 365 | C10: 365 | D10: =IF(B10=C10,"PASS","FAIL") -> PASS | E10: Equals record count when continuous
A11: Production days | B11: =COUNTIF('Daily Energy'!$C$2:$C$366,"Yes") -> 313 | C11: 313 | D11: =IF(B11=C11,"PASS","FAIL") -> PASS
A12: Non-production days | B12: =COUNTIF('Daily Energy'!$C$2:$C$366,"No") -> 52 | C12: 52 | D12: =IF(B12=C12,"PASS","FAIL") -> PASS
A13: Invalid production_day values | B13: =COUNTA('Daily Energy'!$C$2:$C$366)-COUNTIF('Daily Energy'!$C$2:$C$366,"Yes")-COUNTIF('Daily Energy'!$C$2:$C$366,"No") -> 0 | C13: 0 | D13: =IF(B13=C13,"PASS","FAIL") -> PASS | E13: Anything other than Yes / No
A14: Negative operational values (D:J) | B14: =COUNTIF('Daily Energy'!$D$2:$J$366,"<0") -> 0 | C14: 0 | D14: =IF(B14=C14,"PASS","FAIL") -> PASS | E14: units, temperature, grid, solar, CO₂, peak, breakdowns
A15: Units produced on non-production days | B15: =SUMIFS('Daily Energy'!$D$2:$D$366,'Daily Energy'!$C$2:$C$366,"No") -> 0 | C15: 0 | D15: =IF(B15=C15,"PASS","FAIL") -> PASS | E15: Non-production days have no output
A16: Production days with zero units | B16: =COUNTIFS('Daily Energy'!$C$2:$C$366,"Yes",'Daily Energy'!$D$2:$D$366,0) -> 0 | C16: 0 | D16: =IF(B16=C16,"PASS","FAIL") -> PASS
A18: Overall | B18: =IF(COUNTIF(D4:D16,"FAIL")=0,"ALL PASS",COUNTIF(D4:D16,"FAIL")&" FAIL") -> ALL PASS

Sheet Analysis Data
A1: date | B1: day | C1: production_day | D1: units_produced | E1: avg_temp_c | F1: grid_kwh | G1: solar_kwh | H1: total_kwh | I1: month_start | J1: nonprod_kwh | K1: prod_kwh | L1: wasteful_flag | M1: wasteful_seq | N1: prod_seq | P1: prod_day_# | Q1: date | R1: units_produced | S1: avg_temp_c | T1: total_kwh | V1: Notes
A2: ='Daily Energy'!A2 -> 45748 | B2: ='Daily Energy'!B2 -> Tuesday | C2: ='Daily Energy'!C2 -> Yes | D2: ='Daily Energy'!D2 -> 1672 | E2: ='Daily Energy'!E2 -> 22.9 | F2: ='Daily Energy'!F2 -> 11285 | G2: ='Daily Energy'!G2 -> 1824 | H2: =F2+G2 -> 13109 | I2: =DATE(YEAR(A2),MONTH(A2),1) -> 45748 | J2: =IF(C2="No",H2,"") | K2: =IF(C2="Yes",H2,"") -> 13109 | L2: =IF(AND(C2="No",H2>'Analysis Summary'!$B$5),1,0) -> 0 | M2: =IF(L2=1,SUM($L$2:L2),"") | N2: =IF(C2="Yes",COUNTIF($C$2:C2,"Yes"),"") -> 1 | P2: 1 | Q2: =INDEX($A$2:$A$366,MATCH($P2,$N$2:$N$366,0)) -> 45748 | R2: =INDEX($D$2:$D$366,MATCH($P2,$N$2:$N$366,0)) -> 1672 | S2: =INDEX($E$2:$E$366,MATCH($P2,$N$2:$N$366,0)) -> 22.9 | T2: =INDEX($H$2:$H$366,MATCH($P2,$N$2:$N$366,0)) -> 13109 | V2: Columns A–N: one row per day, all formulas linked to Daily Energy (raw data is not modified).
A3: ='Daily Energy'!A3 -> 45749 | B3: ='Daily Energy'!B3 -> Wednesday | C3: ='Daily Energy'!C3 -> Yes | D3: ='Daily Energy'!D3 -> 1476 | E3: ='Daily Energy'!E3 -> 25.9 | F3: ='Daily Energy'!F3 -> 9783 | G3: ='Daily Energy'!G3 -> 1470 | H3: =F3+G3 -> 11253 | I3: =DATE(YEAR(A3),MONTH(A3),1) -> 45748 | J3: =IF(C3="No",H3,"") | K3: =IF(C3="Yes",H3,"") -> 11253 | L3: =IF(AND(C3="No",H3>'Analysis Summary'!$B$5),1,0) -> 0 | M3: =IF(L3=1,SUM($L$2:L3),"") | N3: =IF(C3="Yes",COUNTIF($C$2:C3,"Yes"),"") -> 2 | P3: 2 | Q3: =INDEX($A$2:$A$366,MATCH($P3,$N$2:$N$366,0)) -> 45749 | R3: =INDEX($D$2:$D$366,MATCH($P3,$N$2:$N$366,0)) -> 1476 | S3: =INDEX($E$2:$E$366,MATCH($P3,$N$2:$N$366,0)) -> 25.9 | T3: =INDEX($H$2:$H$366,MATCH($P3,$N$2:$N$366,0)) -> 11253 | V3: Columns P–T: production-day-only extract (313 rows) feeding the regression and scatter chart.
A4: ='Daily Energy'!A4 -> 45750 | B4: ='Daily Energy'!B4 -> Thursday | C4: ='Daily Energy'!C4 -> Yes | D4: ='Daily Energy'!D4 -> 1705 | E4: ='Daily Energy'!E4 -> 25.2 | F4: ='Daily Energy'!F4 -> 11177 | G4: ='Daily Energy'!G4 -> 1940 | H4: =F4+G4 -> 13117 | I4: =DATE(YEAR(A4),MONTH(A4),1) -> 45748 | J4: =IF(C4="No",H4,"") | K4: =IF(C4="Yes",H4,"") -> 13117 | L4: =IF(AND(C4="No",H4>'Analysis Summary'!$B$5),1,0) -> 0 | M4: =IF(L4=1,SUM($L$2:L4),"") | N4: =IF(C4="Yes",COUNTIF($C$2:C4,"Yes"),"") -> 3 | P4: 3 | Q4: =INDEX($A$2:$A$366,MATCH($P4,$N$2:$N$366,0)) -> 45750 | R4: =INDEX($D$2:$D$366,MATCH($P4,$N$2:$N$366,0)) -> 1705 | S4: =INDEX($E$2:$E$366,MATCH($P4,$N$2:$N$366,0)) -> 25.2 | T4: =INDEX($H$2:$H$366,MATCH($P4,$N$2:$N$366,0)) -> 13117 | V4: Block is sized to the 313 production days in this dataset; resize if the data changes.
A5: ='Daily Energy'!A5 -> 45751 | B5: ='Daily Energy'!B5 -> Friday | C5: ='Daily Energy'!C5 -> Yes | D5: ='Daily Energy'!D5 -> 1902 | E5: ='Daily Energy'!E5 -> 25 | F5: ='Daily Energy'!F5 -> 12217 | G5: ='Daily Energy'!G5 -> 2026 | H5: =F5+G5 -> 14243 | I5: =DATE(YEAR(A5),MONTH(A5),1) -> 45748 | J5: =IF(C5="No",H5,"") | K5: =IF(C5="Yes",H5,"") -> 14243 | L5: =IF(AND(C5="No",H5>'Analysis Summary'!$B$5),1,0) -> 0 | M5: =IF(L5=1,SUM($L$2:L5),"") | N5: =IF(C5="Yes",COUNTIF($C$2:C5,"Yes"),"") -> 4 | P5: 4 | Q5: =INDEX($A$2:$A$366,MATCH($P5,$N$2:$N$366,0)) -> 45751 | R5: =INDEX($D$2:$D$366,MATCH($P5,$N$2:$N$366,0)) -> 1902 | S5: =INDEX($E$2:$E$366,MATCH($P5,$N$2:$N$366,0)) -> 25 | T5: =INDEX($H$2:$H$366,MATCH($P5,$N$2:$N$366,0)) -> 14243
A6: ='Daily Energy'!A6 -> 45752 | B6: ='Daily Energy'!B6 -> Saturday | C6: ='Daily Energy'!C6 -> Yes | D6: ='Daily Energy'!D6 -> 1848 | E6: ='Daily Energy'!E6 -> 25.9 | F6: ='Daily Energy'!F6 -> 12005 | G6: ='Daily Energy'!G6 -> 1641 | H6: =F6+G6 -> 13646 | I6: =DATE(YEAR(A6),MONTH(A6),1) -> 45748 | J6: =IF(C6="No",H6,"") | K6: =IF(C6="Yes",H6,"") -> 13646 | L6: =IF(AND(C6="No",H6>'Analysis Summary'!$B$5),1,0) -> 0 | M6: =IF(L6=1,SUM($L$2:L6),"") | N6: =IF(C6="Yes",COUNTIF($C$2:C6,"Yes"),"") -> 5 | P6: 5 | Q6: =INDEX($A$2:$A$366,MATCH($P6,$N$2:$N$366,0)) -> 45752 | R6: =INDEX($D$2:$D$366,MATCH($P6,$N$2:$N$366,0)) -> 1848 | S6: =INDEX($E$2:$E$366,MATCH($P6,$N$2:$N$366,0)) -> 25.9 | T6: =INDEX($H$2:$H$366,MATCH($P6,$N$2:$N$366,0)) -> 13646
A7: ='Daily Energy'!A7 -> 45753 | B7: ='Daily Energy'!B7 -> Sunday | C7: ='Daily Energy'!C7 -> No | D7: ='Daily Energy'!D7 -> 0 | E7: ='Daily Energy'!E7 -> 24.3 | F7: ='Daily Energy'!F7 -> 2486 | G7: ='Daily Energy'!G7 -> 1577 | H7: =F7+G7 -> 4063 | I7: =DATE(YEAR(A7),MONTH(A7),1) -> 45748 | J7: =IF(C7="No",H7,"") -> 4063 | K7: =IF(C7="Yes",H7,"") | L7: =IF(AND(C7="No",H7>'Analysis Summary'!$B$5),1,0) -> 0 | M7: =IF(L7=1,SUM($L$2:L7),"") | N7: =IF(C7="Yes",COUNTIF($C$2:C7,"Yes"),"") | P7: 6 | Q7: =INDEX($A$2:$A$366,MATCH($P7,$N$2:$N$366,0)) -> 45754 | R7: =INDEX($D$2:$D$366,MATCH($P7,$N$2:$N$366,0)) -> 1705 | S7: =INDEX($E$2:$E$366,MATCH($P7,$N$2:$N$366,0)) -> 28.6 | T7: =INDEX($H$2:$H$366,MATCH($P7,$N$2:$N$366,0)) -> 13371
A8: ='Daily Energy'!A8 -> 45754 | B8: ='Daily Energy'!B8 -> Monday | C8: ='Daily Energy'!C8 -> Yes | D8: ='Daily Energy'!D8 -> 1705 | E8: ='Daily Energy'!E8 -> 28.6 | F8: ='Daily Energy'!F8 -> 11877 | G8: ='Daily Energy'!G8 -> 1494 | H8: =F8+G8 -> 13371 | I8: =DATE(YEAR(A8),MONTH(A8),1) -> 45748 | J8: =IF(C8="No",H8,"") | K8: =IF(C8="Yes",H8,"") -> 13371 | L8: =IF(AND(C8="No",H8>'Analysis Summary'!$B$5),1,0) -> 0 | M8: =IF(L8=1,SUM($L$2:L8),"") | N8: =IF(C8="Yes",COUNTIF($C$2:C8,"Yes"),"") -> 6 | P8: 7 | Q8: =INDEX($A$2:$A$366,MATCH($P8,$N$2:$N$366,0)) -> 45755 | R8: =INDEX($D$2:$D$366,MATCH($P8,$N$2:$N$366,0)) -> 1846 | S8: =INDEX($E$2:$E$366,MATCH($P8,$N$2:$N$366,0)) -> 26.7 | T8: =INDEX($H$2:$H$366,MATCH($P8,$N$2:$N$366,0)) -> 14038
A9: ='Daily Energy'!A9 -> 45755 | B9: ='Daily Energy'!B9 -> Tuesday | C9: ='Daily Energy'!C9 -> Yes | D9: ='Daily Energy'!D9 -> 1846 | E9: ='Daily Energy'!E9 -> 26.7 | F9: ='Daily Energy'!F9 -> 12109 | G9: ='Daily Energy'!G9 -> 1929 | H9: =F9+G9 -> 14038 | I9: =DATE(YEAR(A9),MONTH(A9),1) -> 45748 | J9: =IF(C9="No",H9,"") | K9: =IF(C9="Yes",H9,"") -> 14038 | L9: =IF(AND(C9="No",H9>'Analysis Summary'!$B$5),1,0) -> 0 | M9: =IF(L9=1,SUM($L$2:L9),"") | N9: =IF(C9="Yes",COUNTIF($C$2:C9,"Yes"),"") -> 7 | P9: 8 | Q9: =INDEX($A$2:$A$366,MATCH($P9,$N$2:$N$366,0)) -> 45756 | R9: =INDEX($D$2:$D$366,MATCH($P9,$N$2:$N$366,0)) -> 1991 | S9: =INDEX($E$2:$E$366,MATCH($P9,$N$2:$N$366,0)) -> 26.5 | T9: =INDEX($H$2:$H$366,MATCH($P9,$N$2:$N$366,0)) -> 14557
A10: ='Daily Energy'!A10 -> 45756 | B10: ='Daily Energy'!B10 -> Wednesday | C10: ='Daily Energy'!C10 -> Yes | D10: ='Daily Energy'!D10 -> 1991 | E10: ='Daily Energy'!E10 -> 26.5 | F10: ='Daily Energy'!F10 -> 12843 | G10: ='Daily Energy'!G10 -> 1714 | H10: =F10+G10 -> 14557 | I10: =DATE(YEAR(A10),MONTH(A10),1) -> 45748 | J10: =IF(C10="No",H10,"") | K10: =IF(C10="Yes",H10,"") -> 14557 | L10: =IF(AND(C10="No",H10>'Analysis Summary'!$B$5),1,0) -> 0 | M10: =IF(L10=1,SUM($L$2:L10),"") | N10: =IF(C10="Yes",COUNTIF($C$2:C10,"Yes"),"") -> 8 | P10: 9 | Q10: =INDEX($A$2:$A$366,MATCH($P10,$N$2:$N$366,0)) -> 45757 | R10: =INDEX($D$2:$D$366,MATCH($P10,$N$2:$N$366,0)) -> 1529 | S10: =INDEX($E$2:$E$366,MATCH($P10,$N$2:$N$366,0)) -> 26.4 | T10: =INDEX($H$2:$H$366,MATCH($P10,$N$2:$N$366,0)) -> 12029
A11: ='Daily Energy'!A11 -> 45757 | B11: ='Daily Energy'!B11 -> Thursday | C11: ='Daily Energy'!C11 -> Yes | D11: ='Daily Energy'!D11 -> 1529 | E11: ='Daily Energy'!E11 -> 26.4 | F11: ='Daily Energy'!F11 -> 10330 | G11: ='Daily Energy'!G11 -> 1699 | H11: =F11+G11 -> 12029 | I11: =DATE(YEAR(A11),MONTH(A11),1) -> 45748 | J11: =IF(C11="No",H11,"") | K11: =IF(C11="Yes",H11,"") -> 12029 | L11: =IF(AND(C11="No",H11>'Analysis Summary'!$B$5),1,0) -> 0 | M11: =IF(L11=1,SUM($L$2:L11),"") | N11: =IF(C11="Yes",COUNTIF($C$2:C11,"Yes"),"") -> 9 | P11: 10 | Q11: =INDEX($A$2:$A$366,MATCH($P11,$N$2:$N$366,0)) -> 45758 | R11: =INDEX($D$2:$D$366,MATCH($P11,$N$2:$N$366,0)) -> 1828 | S11: =INDEX($E$2:$E$366,MATCH($P11,$N$2:$N$366,0)) -> 26.8 | T11: =INDEX($H$2:$H$366,MATCH($P11,$N$2:$N$366,0)) -> 14225
A12: ='Daily Energy'!A12 -> 45758 | B12: ='Daily Energy'!B12 -> Friday | C12: ='Daily Energy'!C12 -> Yes | D12: ='Daily Energy'!D12 -> 1828 | E12: ='Daily Energy'!E12 -> 26.8 | F12: ='Daily Energy'!F12 -> 12148 | G12: ='Daily Energy'!G12 -> 2077 | H12: =F12+G12 -> 14225 | I12: =DATE(YEAR(A12),MONTH(A12),1) -> 45748 | J12: =IF(C12="No",H12,"") | K12: =IF(C12="Yes",H12,"") -> 14225 | L12: =IF(AND(C12="No",H12>'Analysis Summary'!$B$5),1,0) -> 0 | M12: =IF(L12=1,SUM($L$2:L12),"") | N12: =IF(C12="Yes",COUNTIF($C$2:C12,"Yes"),"") -> 10 | P12: 11 | Q12: =INDEX($A$2:$A$366,MATCH($P12,$N$2:$N$366,0)) -> 45759 | R12: =INDEX($D$2:$D$366,MATCH($P12,$N$2:$N$366,0)) -> 1710 | S12: =INDEX($E$2:$E$366,MATCH($P12,$N$2:$N$366,0)) -> 24 | T12: =INDEX($H$2:$H$366,MATCH($P12,$N$2:$N$366,0)) -> 13195
A13: ='Daily Energy'!A13 -> 45759 | B13: ='Daily Energy'!B13 -> Saturday | C13: ='Daily Energy'!C13 -> Yes | D13: ='Daily Energy'!D13 -> 1710 | E13: ='Daily Energy'!E13 -> 24 | F13: ='Daily Energy'!F13 -> 11688 | G13: ='Daily Energy'!G13 -> 1507 | H13: =F13+G13 -> 13195 | I13: =DATE(YEAR(A13),MONTH(A13),1) -> 45748 | J13: =IF(C13="No",H13,"") | K13: =IF(C13="Yes",H13,"") -> 13195 | L13: =IF(AND(C13="No",H13>'Analysis Summary'!$B$5),1,0) -> 0 | M13: =IF(L13=1,SUM($L$2:L13),"") | N13: =IF(C13="Yes",COUNTIF($C$2:C13,"Yes"),"") -> 11 | P13: 12 | Q13: =INDEX($A$2:$A$366,MATCH($P13,$N$2:$N$366,0)) -> 45761 | R13: =INDEX($D$2:$D$366,MATCH($P13,$N$2:$N$366,0)) -> 1768 | S13: =INDEX($E$2:$E$366,MATCH($P13,$N$2:$N$366,0)) -> 28.3 | T13: =INDEX($H$2:$H$366,MATCH($P13,$N$2:$N$366,0)) -> 13363
A14: ='Daily Energy'!A14 -> 45760 | B14: ='Daily Energy'!B14 -> Sunday | C14: ='Daily Energy'!C14 -> No | D14: ='Daily Energy'!D14 -> 0 | E14: ='Daily Energy'!E14 -> 26 | F14: ='Daily Energy'!F14 -> 2014 | G14: ='Daily Energy'!G14 -> 1475 | H14: =F14+G14 -> 3489 | I14: =DATE(YEAR(A14),MONTH(A14),1) -> 45748 | J14: =IF(C14="No",H14,"") -> 3489 | K14: =IF(C14="Yes",H14,"") | L14: =IF(AND(C14="No",H14>'Analysis Summary'!$B$5),1,0) -> 0 | M14: =IF(L14=1,SUM($L$2:L14),"") | N14: =IF(C14="Yes",COUNTIF($C$2:C14,"Yes"),"") | P14: 13 | Q14: =INDEX($A$2:$A$366,MATCH($P14,$N$2:$N$366,0)) -> 45762 | R14: =INDEX($D$2:$D$366,MATCH($P14,$N$2:$N$366,0)) -> 1591 | S14: =INDEX($E$2:$E$366,MATCH($P14,$N$2:$N$366,0)) -> 27.7 | T14: =INDEX($H$2:$H$366,MATCH($P14,$N$2:$N$366,0)) -> 12128
A15: ='Daily Energy'!A15 -> 45761 | B15: ='Daily Energy'!B15 -> Monday | C15: ='Daily Energy'!C15 -> Yes | D15: ='Daily Energy'!D15 -> 1768 | E15: ='Daily Energy'!E15 -> 28.3 | F15: ='Daily Energy'!F15 -> 11944 | G15: ='Daily Energy'!G15 -> 1419 | H15: =F15+G15 -> 13363 | I15: =DATE(YEAR(A15),MONTH(A15),1) -> 45748 | J15: =IF(C15="No",H15,"") | K15: =IF(C15="Yes",H15,"") -> 13363 | L15: =IF(AND(C15="No",H15>'Analysis Summary'!$B$5),1,0) -> 0 | M15: =IF(L15=1,SUM($L$2:L15),"") | N15: =IF(C15="Yes",COUNTIF($C$2:C15,"Yes"),"") -> 12 | P15: 14 | Q15: =INDEX($A$2:$A$366,MATCH($P15,$N$2:$N$366,0)) -> 45763 | R15: =INDEX($D$2:$D$366,MATCH($P15,$N$2:$N$366,0)) -> 1813 | S15: =INDEX($E$2:$E$366,MATCH($P15,$N$2:$N$366,0)) -> 27.3 | T15: =INDEX($H$2:$H$366,MATCH($P15,$N$2:$N$366,0)) -> 13753
A16: ='Daily Energy'!A16 -> 45762 | B16: ='Daily Energy'!B16 -> Tuesday | C16: ='Daily Energy'!C16 -> Yes | D16: ='Daily Energy'!D16 -> 1591 | E16: ='Daily Energy'!E16 -> 27.7 | F16: ='Daily Energy'!F16 -> 11009 | G16: ='Daily Energy'!G16 -> 1119 | H16: =F16+G16 -> 12128 | I16: =DATE(YEAR(A16),MONTH(A16),1) -> 45748 | J16: =IF(C16="No",H16,"") | K16: =IF(C16="Yes",H16,"") -> 12128 | L16: =IF(AND(C16="No",H16>'Analysis Summary'!$B$5),1,0) -> 0 | M16: =IF(L16=1,SUM($L$2:L16),"") | N16: =IF(C16="Yes",COUNTIF($C$2:C16,"Yes"),"") -> 13 | P16: 15 | Q16: =INDEX($A$2:$A$366,MATCH($P16,$N$2:$N$366,0)) -> 45764 | R16: =INDEX($D$2:$D$366,MATCH($P16,$N$2:$N$366,0)) -> 1724 | S16: =INDEX($E$2:$E$366,MATCH($P16,$N$2:$N$366,0)) -> 28.2 | T16: =INDEX($H$2:$H$366,MATCH($P16,$N$2:$N$366,0)) -> 13112
... A314: ='Daily Energy'!A314 -> 46060 | B314: ='Daily Energy'!B314 -> Saturday | C314: ='Daily Energy'!C314 -> Yes | D314: ='Daily Energy'!D314 -> 1902 | E314: ='Daily Energy'!E314 -> 20.8 | F314: ='Daily Energy'!F314 -> 12453 | G314: ='Daily Energy'!G314 -> 1556 | H314: =F314+G314 -> 14009 | I314: =DATE(YEAR(A314),MONTH(A314),1) -> 46054 | J314: =IF(C314="No",H314,"") | K314: =IF(C314="Yes",H314,"") -> 14009 | L314: =IF(AND(C314="No",H314>'Analysis Summary'!$B$5),1,0) -> 0 | M314: =IF(L314=1,SUM($L$2:L314),"") | N314: =IF(C314="Yes",COUNTIF($C$2:C314,"Yes"),"") -> 269 | P314: 313 | Q314: =INDEX($A$2:$A$366,MATCH($P314,$N$2:$N$366,0)) -> 46112 | R314: =INDEX($D$2:$D$366,MATCH($P314,$N$2:$N$366,0)) -> 1853 | S314: =INDEX($E$2:$E$366,MATCH($P314,$N$2:$N$366,0)) -> 23.7 | T314: =INDEX($H$2:$H$366,MATCH($P314,$N$2:$N$366,0)) -> 14492
A315: ='Daily Energy'!A315 -> 46061 | B315: ='Daily Energy'!B315 -> Sunday | C315: ='Daily Energy'!C315 -> No | D315: ='Daily Energy'!D315 -> 0 | E315: ='Daily Energy'!E315 -> 19.8 | F315: ='Daily Energy'!F315 -> 2469 | G315: ='Daily Energy'!G315 -> 1873 | H315: =F315+G315 -> 4342 | I315: =DATE(YEAR(A315),MONTH(A315),1) -> 46054 | J315: =IF(C315="No",H315,"") -> 4342 | K315: =IF(C315="Yes",H315,"") | L315: =IF(AND(C315="No",H315>'Analysis Summary'!$B$5),1,0) -> 0 | M315: =IF(L315=1,SUM($L$2:L315),"") | N315: =IF(C315="Yes",COUNTIF($C$2:C315,"Yes"),"")
A316: ='Daily Energy'!A316 -> 46062 | B316: ='Daily Energy'!B316 -> Monday | C316: ='Daily Energy'!C316 -> Yes | D316: ='Daily Energy'!D316 -> 1892 | E316: ='Daily Energy'!E316 -> 20.7 | F316: ='Daily Energy'!F316 -> 12287 | G316: ='Daily Energy'!G316 -> 1733 | H316: =F316+G316 -> 14020 | I316: =DATE(YEAR(A316),MONTH(A316),1) -> 46054 | J316: =IF(C316="No",H316,"") | K316: =IF(C316="Yes",H316,"") -> 14020 | L316: =IF(AND(C316="No",H316>'Analysis Summary'!$B$5),1,0) -> 0 | M316: =IF(L316=1,SUM($L$2:L316),"") | N316: =IF(C316="Yes",COUNTIF($C$2:C316,"Yes"),"") -> 270
A317: ='Daily Energy'!A317 -> 46063 | B317: ='Daily Energy'!B317 -> Tuesday | C317: ='Daily Energy'!C317 -> Yes | D317: ='Daily Energy'!D317 -> 1772 | E317: ='Daily Energy'!E317 -> 20.4 | F317: ='Daily Energy'!F317 -> 12155 | G317: ='Daily Energy'!G317 -> 1711 | H317: =F317+G317 -> 13866 | I317: =DATE(YEAR(A317),MONTH(A317),1) -> 46054 | J317: =IF(C317="No",H317,"") | K317: =IF(C317="Yes",H317,"") -> 13866 | L317: =IF(AND(C317="No",H317>'Analysis Summary'!$B$5),1,0) -> 0 | M317: =IF(L317=1,SUM($L$2:L317),"") | N317: =IF(C317="Yes",COUNTIF($C$2:C317,"Yes"),"") -> 271
A318: ='Daily Energy'!A318 -> 46064 | B318: ='Daily Energy'!B318 -> Wednesday | C318: ='Daily Energy'!C318 -> Yes | D318: ='Daily Energy'!D318 -> 1640 | E318: ='Daily Energy'!E318 -> 18.4 | F318: ='Daily Energy'!F318 -> 10551 | G318: ='Daily Energy'!G318 -> 1940 | H318: =F318+G318 -> 12491 | I318: =DATE(YEAR(A318),MONTH(A318),1) -> 46054 | J318: =IF(C318="No",H318,"") | K318: =IF(C318="Yes",H318,"") -> 12491 | L318: =IF(AND(C318="No",H318>'Analysis Summary'!$B$5),1,0) -> 0 | M318: =IF(L318=1,SUM($L$2:L318),"") | N318: =IF(C318="Yes",COUNTIF($C$2:C318,"Yes"),"") -> 272
A319: ='Daily Energy'!A319 -> 46065 | B319: ='Daily Energy'!B319 -> Thursday | C319: ='Daily Energy'!C319 -> Yes | D319: ='Daily Energy'!D319 -> 1865 | E319: ='Daily Energy'!E319 -> 23.2 | F319: ='Daily Energy'!F319 -> 12432 | G319: ='Daily Energy'!G319 -> 1693 | H319: =F319+G319 -> 14125 | I319: =DATE(YEAR(A319),MONTH(A319),1) -> 46054 | J319: =IF(C319="No",H319,"") | K319: =IF(C319="Yes",H319,"") -> 14125 | L319: =IF(AND(C319="No",H319>'Analysis Summary'!$B$5),1,0) -> 0 | M319: =IF(L319=1,SUM($L$2:L319),"") | N319: =IF(C319="Yes",COUNTIF($C$2:C319,"Yes"),"") -> 273
A320: ='Daily Energy'!A320 -> 46066 | B320: ='Daily Energy'!B320 -> Friday | C320: ='Daily Energy'!C320 -> Yes | D320: ='Daily Energy'!D320 -> 1783 | E320: ='Daily Energy'!E320 -> 20.9 | F320: ='Daily Energy'!F320 -> 11550 | G320: ='Daily Energy'!G320 -> 1790 | H320: =F320+G320 -> 13340 | I320: =DATE(YEAR(A320),MONTH(A320),1) -> 46054 | J320: =IF(C320="No",H320,"") | K320: =IF(C320="Yes",H320,"") -> 13340 | L320: =IF(AND(C320="No",H320>'Analysis Summary'!$B$5),1,0) -> 0 | M320: =IF(L320=1,SUM($L$2:L320),"") | N320: =IF(C320="Yes",COUNTIF($C$2:C320,"Yes"),"") -> 274
A321: ='Daily Energy'!A321 -> 46067 | B321: ='Daily Energy'!B321 -> Saturday | C321: ='Daily Energy'!C321 -> Yes | D321: ='Daily Energy'!D321 -> 1681 | E321: ='Daily Energy'!E321 -> 21.1 | F321: ='Daily Energy'!F321 -> 10577 | G321: ='Daily Energy'!G321 -> 1584 | H321: =F321+G321 -> 12161 | I321: =DATE(YEAR(A321),MONTH(A321),1) -> 46054 | J321: =IF(C321="No",H321,"") | K321: =IF(C321="Yes",H321,"") -> 12161 | L321: =IF(AND(C321="No",H321>'Analysis Summary'!$B$5),1,0) -> 0 | M321: =IF(L321=1,SUM($L$2:L321),"") | N321: =IF(C321="Yes",COUNTIF($C$2:C321,"Yes"),"") -> 275
A322: ='Daily Energy'!A322 -> 46068 | B322: ='Daily Energy'!B322 -> Sunday | C322: ='Daily Energy'!C322 -> No | D322: ='Daily Energy'!D322 -> 0 | E322: ='Daily Energy'!E322 -> 22.5 | F322: ='Daily Energy'!F322 -> 2377 | G322: ='Daily Energy'!G322 -> 1377 | H322: =F322+G322 -> 3754 | I322: =DATE(YEAR(A322),MONTH(A322),1) -> 46054 | J322: =IF(C322="No",H322,"") -> 3754 | K322: =IF(C322="Yes",H322,"") | L322: =IF(AND(C322="No",H322>'Analysis Summary'!$B$5),1,0) -> 0 | M322: =IF(L322=1,SUM($L$2:L322),"") | N322: =IF(C322="Yes",COUNTIF($C$2:C322,"Yes"),"")
A323: ='Daily Energy'!A323 -> 46069 | B323: ='Daily Energy'!B323 -> Monday | C323: ='Daily Energy'!C323 -> Yes | D323: ='Daily Energy'!D323 -> 1882 | E323: ='Daily Energy'!E323 -> 23.5 | F323: ='Daily Energy'!F323 -> 11975 | G323: ='Daily Energy'!G323 -> 1583 | H323: =F323+G323 -> 13558 | I323: =DATE(YEAR(A323),MONTH(A323),1) -> 46054 | J323: =IF(C323="No",H323,"") | K323: =IF(C323="Yes",H323,"") -> 13558 | L323: =IF(AND(C323="No",H323>'Analysis Summary'!$B$5),1,0) -> 0 | M323: =IF(L323=1,SUM($L$2:L323),"") | N323: =IF(C323="Yes",COUNTIF($C$2:C323,"Yes"),"") -> 276
A324: ='Daily Energy'!A324 -> 46070 | B324: ='Daily Energy'!B324 -> Tuesday | C324: ='Daily Energy'!C324 -> Yes | D324: ='Daily Energy'!D324 -> 1941 | E324: ='Daily Energy'!E324 -> 21.8 | F324: ='Daily Energy'!F324 -> 13203 | G324: ='Daily Energy'!G324 -> 1502 | H324: =F324+G324 -> 14705 | I324: =DATE(YEAR(A324),MONTH(A324),1) -> 46054 | J324: =IF(C324="No",H324,"") | K324: =IF(C324="Yes",H324,"") -> 14705 | L324: =IF(AND(C324="No",H324>'Analysis Summary'!$B$5),1,0) -> 0 | M324: =IF(L324=1,SUM($L$2:L324),"") | N324: =IF(C324="Yes",COUNTIF($C$2:C324,"Yes"),"") -> 277
A325: ='Daily Energy'!A325 -> 46071 | B325: ='Daily Energy'!B325 -> Wednesday | C325: ='Daily Energy'!C325 -> Yes | D325: ='Daily Energy'!D325 -> 1899 | E325: ='Daily Energy'!E325 -> 21.2 | F325: ='Daily Energy'!F325 -> 12429 | G325: ='Daily Energy'!G325 -> 1432 | H325: =F325+G325 -> 13861 | I325: =DATE(YEAR(A325),MONTH(A325),1) -> 46054 | J325: =IF(C325="No",H325,"") | K325: =IF(C325="Yes",H325,"") -> 13861 | L325: =IF(AND(C325="No",H325>'Analysis Summary'!$B$5),1,0) -> 0 | M325: =IF(L325=1,SUM($L$2:L325),"") | N325: =IF(C325="Yes",COUNTIF($C$2:C325,"Yes"),"") -> 278
A326: ='Daily Energy'!A326 -> 46072 | B326: ='Daily Energy'!B326 -> Thursday | C326: ='Daily Energy'!C326 -> Yes | D326: ='Daily Energy'!D326 -> 1612 | E326: ='Daily Energy'!E326 -> 21.8 | F326: ='Daily Energy'!F326 -> 10970 | G326: ='Daily Energy'!G326 -> 1261 | H326: =F326+G326 -> 12231 | I326: =DATE(YEAR(A326),MONTH(A326),1) -> 46054 | J326: =IF(C326="No",H326,"") | K326: =IF(C326="Yes",H326,"") -> 12231 | L326: =IF(AND(C326="No",H326>'Analysis Summary'!$B$5),1,0) -> 0 | M326: =IF(L326=1,SUM($L$2:L326),"") | N326: =IF(C326="Yes",COUNTIF($C$2:C326,"Yes"),"") -> 279
... A366: ='Daily Energy'!A366 -> 46112 | B366: ='Daily Energy'!B366 -> Tuesday | C366: ='Daily Energy'!C366 -> Yes | D366: ='Daily Energy'!D366 -> 1853 | E366: ='Daily Energy'!E366 -> 23.7 | F366: ='Daily Energy'!F366 -> 12752 | G366: ='Daily Energy'!G366 -> 1740 | H366: =F366+G366 -> 14492 | I366: =DATE(YEAR(A366),MONTH(A366),1) -> 46082 | J366: =IF(C366="No",H366,"") | K366: =IF(C366="Yes",H366,"") -> 14492 | L366: =IF(AND(C366="No",H366>'Analysis Summary'!$B$5),1,0) -> 0 | M366: =IF(L366=1,SUM($L$2:L366),"") | N366: =IF(C366="Yes",COUNTIF($C$2:C366,"Yes"),"") -> 313

Sheet KPI Summary
A1: KPI Summary
A2: Annual KPIs, 01-Apr-2025 to 31-Mar-2026 — formulas link to Analysis Data
A3: KPI | B3: Value | C3: Unit | D3: Definition
A4: Total Energy | B4: =SUM('Analysis Data'!$H$2:$H$366) -> 4489639 | C4: kWh | D4: Grid + solar, all 365 days
A5: Grid Energy | B5: =SUM('Analysis Data'!$F$2:$F$366) -> 4014871 | C5: kWh | D5: Sum of grid_kwh
A6: Solar Energy | B6: =SUM('Analysis Data'!$G$2:$G$366) -> 474768 | C6: kWh | D6: Sum of solar_kwh
A7: Solar Share | B7: =B6/B4 -> 0.10574748 | C7: % | D7: Solar ÷ total energy (annual totals)
A8: Total Units Produced | B8: =SUM('Analysis Data'!$D$2:$D$366) -> 566026 | C8: units | D8: All units are produced on production days
A9: Production Days | B9: =COUNTIF('Analysis Data'!$C$2:$C$366,"Yes") -> 313 | C9: days | D9: production_day = Yes
A10: Non-Production Days | B10: =COUNTIF('Analysis Data'!$C$2:$C$366,"No") -> 52 | C10: days | D10: production_day = No
A11: Production-Day Energy | B11: =SUM('Analysis Data'!$K$2:$K$366) -> 4271630 | C11: kWh | D11: Total energy on production days only
A12: Production-Day Energy Intensity | B12: =B11/B8 -> 7.5467028 | C12: kWh/unit | D12: Production-day energy ÷ production-day units
A13: Non-Production Energy | B13: =SUM('Analysis Data'!$J$2:$J$366) -> 218009 | C13: kWh | D13: Total energy on non-production days
A14: Non-Production Share of Total Energy | B14: =B13/B4 -> 0.048558247 | C14: % | D14: Non-production energy ÷ total energy
A15: Maximum Peak Demand | B15: =MAX('Daily Energy'!$I$2:$I$366) -> 520 | C15: kW | D15: Maximum daily peak_demand_kw (never summed)
A16: Total Machine Breakdowns | B16: =SUM('Daily Energy'!$J$2:$J$366) -> 364 | C16: count | D16: Sum of machine_breakdowns
A17: Records | B17: =COUNT('Analysis Data'!$A$2:$A$366) -> 365 | C17: days | D17: Daily rows in the dataset
A18: Potentially Wasteful Days | B18: ='Analysis Summary'!B7 -> 3 | C18: days | D18: Non-production days above the 95th-percentile screen
A19: Wasteful-Day Threshold | B19: ='Analysis Summary'!B5 -> 4687.7 | C19: kWh | D19: 95th percentile of non-production daily kWh
A20: Lowest Monthly Solar Share | B20: =MIN('Monthly Analysis'!I5:I16) -> 0.052037385 | C20: % | D20: From Monthly Analysis
A21: Highest Monthly Solar Share | B21: =MAX('Monthly Analysis'!I5:I16) -> 0.13761415 | C21: % | D21: From Monthly Analysis

Sheet Monthly Analysis
A1: Monthly Analysis
A2: Intensity = monthly production-day energy ÷ monthly production-day units (not an average of daily ratios). Peak = monthly maximum.
A4: Month | B4: Month start | C4: Days | D4: Production days | E4: Non-production days | F4: Grid (kWh) | G4: Solar (kWh) | H4: Total energy (kWh) | I4: Solar share | J4: Production-day energy (kWh) | K4: Production-day units | L4: Intensity (kWh/unit) | M4: Non-production energy (kWh) | N4: Peak demand (kW) | O4: Machine breakdowns | P4: Avg temp, production days (°C)
A5: =TEXT(B5,"mmm-yy") -> Apr-25 | B5: =DATE(YEAR(MIN('Daily Energy'!$A$2:$A$366)),MONTH(MIN('Daily Energy'!$A$2:$A$366)),1) -> 45748 | C5: =COUNTIF('Analysis Data'!$I$2:$I$366,B5) -> 30 | D5: =COUNTIFS('Analysis Data'!$I$2:$I$366,B5,'Analysis Data'!$C$2:$C$366,"Yes") -> 26 | E5: =COUNTIFS('Analysis Data'!$I$2:$I$366,B5,'Analysis Data'!$C$2:$C$366,"No") -> 4 | F5: =SUMIFS('Analysis Data'!$F$2:$F$366,'Analysis Data'!$I$2:$I$366,B5) -> 316499 | G5: =SUMIFS('Analysis Data'!$G$2:$G$366,'Analysis Data'!$I$2:$I$366,B5) -> 48738 | H5: =F5+G5 -> 365237 | I5: =IF(H5=0,0,G5/H5) -> 0.13344212 | J5: =SUMIFS('Analysis Data'!$H$2:$H$366,'Analysis Data'!$I$2:$I$366,B5,'Analysis Data'!$C$2:$C$366,"Yes") -> 349141 | K5: =SUMIFS('Analysis Data'!$D$2:$D$366,'Analysis Data'!$I$2:$I$366,B5,'Analysis Data'!$C$2:$C$366,"Yes") -> 45912 | L5: =IF(K5=0,0,J5/K5) -> 7.6045696 | M5: =SUMIFS('Analysis Data'!$H$2:$H$366,'Analysis Data'!$I$2:$I$366,B5,'Analysis Data'!$C$2:$C$366,"No") -> 16096 | N5: =_xlfn.MAXIFS('Daily Energy'!$I$2:$I$366,'Analysis Data'!$I$2:$I$366,B5) -> 519 | O5: =SUMIFS('Daily Energy'!$J$2:$J$366,'Analysis Data'!$I$2:$I$366,B5) -> 31 | P5: =AVERAGEIFS('Analysis Data'!$E$2:$E$366,'Analysis Data'!$I$2:$I$366,B5,'Analysis Data'!$C$2:$C$366,"Yes") -> 26.780769
A6: =TEXT(B6,"mmm-yy") -> May-25 | B6: =EDATE(B5,1) -> 45778 | C6: =COUNTIF('Analysis Data'!$I$2:$I$366,B6) -> 31 | D6: =COUNTIFS('Analysis Data'!$I$2:$I$366,B6,'Analysis Data'!$C$2:$C$366,"Yes") -> 27 | E6: =COUNTIFS('Analysis Data'!$I$2:$I$366,B6,'Analysis Data'!$C$2:$C$366,"No") -> 4 | F6: =SUMIFS('Analysis Data'!$F$2:$F$366,'Analysis Data'!$I$2:$I$366,B6) -> 353699 | G6: =SUMIFS('Analysis Data'!$G$2:$G$366,'Analysis Data'!$I$2:$I$366,B6) -> 49544 | H6: =F6+G6 -> 403243 | I6: =IF(H6=0,0,G6/H6) -> 0.12286388 | J6: =SUMIFS('Analysis Data'!$H$2:$H$366,'Analysis Data'!$I$2:$I$366,B6,'Analysis Data'!$C$2:$C$366,"Yes") -> 384875 | K6: =SUMIFS('Analysis Data'!$D$2:$D$366,'Analysis Data'!$I$2:$I$366,B6,'Analysis Data'!$C$2:$C$366,"Yes") -> 49216 | L6: =IF(K6=0,0,J6/K6) -> 7.8201195 | M6: =SUMIFS('Analysis Data'!$H$2:$H$366,'Analysis Data'!$I$2:$I$366,B6,'Analysis Data'!$C$2:$C$366,"No") -> 18368 | N6: =_xlfn.MAXIFS('Daily Energy'!$I$2:$I$366,'Analysis Data'!$I$2:$I$366,B6) -> 518 | O6: =SUMIFS('Daily Energy'!$J$2:$J$366,'Analysis Data'!$I$2:$I$366,B6) -> 30 | P6: =AVERAGEIFS('Analysis Data'!$E$2:$E$366,'Analysis Data'!$I$2:$I$366,B6,'Analysis Data'!$C$2:$C$366,"Yes") -> 29.659259
A7: =TEXT(B7,"mmm-yy") -> Jun-25 | B7: =EDATE(B6,1) -> 45809 | C7: =COUNTIF('Analysis Data'!$I$2:$I$366,B7) -> 30 | D7: =COUNTIFS('Analysis Data'!$I$2:$I$366,B7,'Analysis Data'!$C$2:$C$366,"Yes") -> 25 | E7: =COUNTIFS('Analysis Data'!$I$2:$I$366,B7,'Analysis Data'!$C$2:$C$366,"No") -> 5 | F7: =SUMIFS('Analysis Data'!$F$2:$F$366,'Analysis Data'!$I$2:$I$366,B7) -> 347954 | G7: =SUMIFS('Analysis Data'!$G$2:$G$366,'Analysis Data'!$I$2:$I$366,B7) -> 20853 | H7: =F7+G7 -> 368807 | I7: =IF(H7=0,0,G7/H7) -> 0.056541768 | J7: =SUMIFS('Analysis Data'!$H$2:$H$366,'Analysis Data'!$I$2:$I$366,B7,'Analysis Data'!$C$2:$C$366,"Yes") -> 346288 | K7: =SUMIFS('Analysis Data'!$D$2:$D$366,'Analysis Data'!$I$2:$I$366,B7,'Analysis Data'!$C$2:$C$366,"Yes") -> 45860 | L7: =IF(K7=0,0,J7/K7) -> 7.5509812 | M7: =SUMIFS('Analysis Data'!$H$2:$H$366,'Analysis Data'!$I$2:$I$366,B7,'Analysis Data'!$C$2:$C$366,"No") -> 22519 | N7: =_xlfn.MAXIFS('Daily Energy'!$I$2:$I$366,'Analysis Data'!$I$2:$I$366,B7) -> 517 | O7: =SUMIFS('Daily Energy'!$J$2:$J$366,'Analysis Data'!$I$2:$I$366,B7) -> 28 | P7: =AVERAGEIFS('Analysis Data'!$E$2:$E$366,'Analysis Data'!$I$2:$I$366,B7,'Analysis Data'!$C$2:$C$366,"Yes") -> 32.108
A8: =TEXT(B8,"mmm-yy") -> Jul-25 | B8: =EDATE(B7,1) -> 45839 | C8: =COUNTIF('Analysis Data'!$I$2:$I$366,B8) -> 31 | D8: =COUNTIFS('Analysis Data'!$I$2:$I$366,B8,'Analysis Data'!$C$2:$C$366,"Yes") -> 27 | E8: =COUNTIFS('Analysis Data'!$I$2:$I$366,B8,'Analysis Data'!$C$2:$C$366,"No") -> 4 | F8: =SUMIFS('Analysis Data'!$F$2:$F$366,'Analysis Data'!$I$2:$I$366,B8) -> 367272 | G8: =SUMIFS('Analysis Data'!$G$2:$G$366,'Analysis Data'!$I$2:$I$366,B8) -> 20161 | H8: =F8+G8 -> 387433 | I8: =IF(H8=0,0,G8/H8) -> 0.052037385 | J8: =SUMIFS('Analysis Data'!$H$2:$H$366,'Analysis Data'!$I$2:$I$366,B8,'Analysis Data'!$C$2:$C$366,"Yes") -> 371065 | K8: =SUMIFS('Analysis Data'!$D$2:$D$366,'Analysis Data'!$I$2:$I$366,B8,'Analysis Data'!$C$2:$C$366,"Yes") -> 48649 | L8: =IF(K8=0,0,J8/K8) -> 7.6273921 | M8: =SUMIFS('Analysis Data'!$H$2:$H$366,'Analysis Data'!$I$2:$I$366,B8,'Analysis Data'!$C$2:$C$366,"No") -> 16368 | N8: =_xlfn.MAXIFS('Daily Energy'!$I$2:$I$366,'Analysis Data'!$I$2:$I$366,B8) -> 516 | O8: =SUMIFS('Daily Energy'!$J$2:$J$366,'Analysis Data'!$I$2:$I$366,B8) -> 33 | P8: =AVERAGEIFS('Analysis Data'!$E$2:$E$366,'Analysis Data'!$I$2:$I$366,B8,'Analysis Data'!$C$2:$C$366,"Yes") -> 32.892593
A9: =TEXT(B9,"mmm-yy") -> Aug-25 | B9: =EDATE(B8,1) -> 45870 | C9: =COUNTIF('Analysis Data'!$I$2:$I$366,B9) -> 31 | D9: =COUNTIFS('Analysis Data'!$I$2:$I$366,B9,'Analysis Data'!$C$2:$C$366,"Yes") -> 26 | E9: =COUNTIFS('Analysis Data'!$I$2:$I$366,B9,'Analysis Data'!$C$2:$C$366,"No") -> 5 | F9: =SUMIFS('Analysis Data'!$F$2:$F$366,'Analysis Data'!$I$2:$I$366,B9) -> 358530 | G9: =SUMIFS('Analysis Data'!$G$2:$G$366,'Analysis Data'!$I$2:$I$366,B9) -> 22863 | H9: =F9+G9 -> 381393 | I9: =IF(H9=0,0,G9/H9) -> 0.05994604 | J9: =SUMIFS('Analysis Data'!$H$2:$H$366,'Analysis Data'!$I$2:$I$366,B9,'Analysis Data'!$C$2:$C$366,"Yes") -> 360383 | K9: =SUMIFS('Analysis Data'!$D$2:$D$366,'Analysis Data'!$I$2:$I$366,B9,'Analysis Data'!$C$2:$C$366,"Yes") -> 47568 | L9: =IF(K9=0,0,J9/K9) -> 7.5761646 | M9: =SUMIFS('Analysis Data'!$H$2:$H$366,'Analysis Data'!$I$2:$I$366,B9,'Analysis Data'!$C$2:$C$366,"No") -> 21010 | N9: =_xlfn.MAXIFS('Daily Energy'!$I$2:$I$366,'Analysis Data'!$I$2:$I$366,B9) -> 511 | O9: =SUMIFS('Daily Energy'!$J$2:$J$366,'Analysis Data'!$I$2:$I$366,B9) -> 24 | P9: =AVERAGEIFS('Analysis Data'!$E$2:$E$366,'Analysis Data'!$I$2:$I$366,B9,'Analysis Data'!$C$2:$C$366,"Yes") -> 32.184615
A10: =TEXT(B10,"mmm-yy") -> Sep-25 | B10: =EDATE(B9,1) -> 45901 | C10: =COUNTIF('Analysis Data'!$I$2:$I$366,B10) -> 30 | D10: =COUNTIFS('Analysis Data'!$I$2:$I$366,B10,'Analysis Data'!$C$2:$C$366,"Yes") -> 26 | E10: =COUNTIFS('Analysis Data'!$I$2:$I$366,B10,'Analysis Data'!$C$2:$C$366,"No") -> 4 | F10: =SUMIFS('Analysis Data'!$F$2:$F$366,'Analysis Data'!$I$2:$I$366,B10) -> 344162 | G10: =SUMIFS('Analysis Data'!$G$2:$G$366,'Analysis Data'!$I$2:$I$366,B10) -> 20423 | H10: =F10+G10 -> 364585 | I10: =IF(H10=0,0,G10/H10) -> 0.056017115 | J10: =SUMIFS('Analysis Data'!$H$2:$H$366,'Analysis Data'!$I$2:$I$366,B10,'Analysis Data'!$C$2:$C$366,"Yes") -> 348929 | K10: =SUMIFS('Analysis Data'!$D$2:$D$366,'Analysis Data'!$I$2:$I$366,B10,'Analysis Data'!$C$2:$C$366,"Yes") -> 46991 | L10: =IF(K10=0,0,J10/K10) -> 7.4254432 | M10: =SUMIFS('Analysis Data'!$H$2:$H$366,'Analysis Data'!$I$2:$I$366,B10,'Analysis Data'!$C$2:$C$366,"No") -> 15656 | N10: =_xlfn.MAXIFS('Daily Energy'!$I$2:$I$366,'Analysis Data'!$I$2:$I$366,B10) -> 519 | O10: =SUMIFS('Daily Energy'!$J$2:$J$366,'Analysis Data'!$I$2:$I$366,B10) -> 27 | P10: =AVERAGEIFS('Analysis Data'!$E$2:$E$366,'Analysis Data'!$I$2:$I$366,B10,'Analysis Data'!$C$2:$C$366,"Yes") -> 30.35
A11: =TEXT(B11,"mmm-yy") -> Oct-25 | B11: =EDATE(B10,1) -> 45931 | C11: =COUNTIF('Analysis Data'!$I$2:$I$366,B11) -> 31 | D11: =COUNTIFS('Analysis Data'!$I$2:$I$366,B11,'Analysis Data'!$C$2:$C$366,"Yes") -> 27 | E11: =COUNTIFS('Analysis Data'!$I$2:$I$366,B11,'Analysis Data'!$C$2:$C$366,"No") -> 4 | F11: =SUMIFS('Analysis Data'!$F$2:$F$366,'Analysis Data'!$I$2:$I$366,B11) -> 340717 | G11: =SUMIFS('Analysis Data'!$G$2:$G$366,'Analysis Data'!$I$2:$I$366,B11) -> 49162 | H11: =F11+G11 -> 389879 | I11: =IF(H11=0,0,G11/H11) -> 0.12609553 | J11: =SUMIFS('Analysis Data'!$H$2:$H$366,'Analysis Data'!$I$2:$I$366,B11,'Analysis Data'!$C$2:$C$366,"Yes") -> 373465 | K11: =SUMIFS('Analysis Data'!$D$2:$D$366,'Analysis Data'!$I$2:$I$366,B11,'Analysis Data'!$C$2:$C$366,"Yes") -> 49376 | L11: =IF(K11=0,0,J11/K11) -> 7.5636949 | M11: =SUMIFS('Analysis Data'!$H$2:$H$366,'Analysis Data'!$I$2:$I$366,B11,'Analysis Data'!$C$2:$C$366,"No") -> 16414 | N11: =_xlfn.MAXIFS('Daily Energy'!$I$2:$I$366,'Analysis Data'!$I$2:$I$366,B11) -> 513 | O11: =SUMIFS('Daily Energy'!$J$2:$J$366,'Analysis Data'!$I$2:$I$366,B11) -> 36 | P11: =AVERAGEIFS('Analysis Data'!$E$2:$E$366,'Analysis Data'!$I$2:$I$366,B11,'Analysis Data'!$C$2:$C$366,"Yes") -> 27.477778
A12: =TEXT(B12,"mmm-yy") -> Nov-25 | B12: =EDATE(B11,1) -> 45962 | C12: =COUNTIF('Analysis Data'!$I$2:$I$366,B12) -> 30 | D12: =COUNTIFS('Analysis Data'!$I$2:$I$366,B12,'Analysis Data'!$C$2:$C$366,"Yes") -> 25 | E12: =COUNTIFS('Analysis Data'!$I$2:$I$366,B12,'Analysis Data'!$C$2:$C$366,"No") -> 5 | F12: =SUMIFS('Analysis Data'!$F$2:$F$366,'Analysis Data'!$I$2:$I$366,B12) -> 309370 | G12: =SUMIFS('Analysis Data'!$G$2:$G$366,'Analysis Data'!$I$2:$I$366,B12) -> 48512 | H12: =F12+G12 -> 357882 | I12: =IF(H12=0,0,G12/H12) -> 0.13555306 | J12: =SUMIFS('Analysis Data'!$H$2:$H$366,'Analysis Data'!$I$2:$I$366,B12,'Analysis Data'!$C$2:$C$366,"Yes") -> 337356 | K12: =SUMIFS('Analysis Data'!$D$2:$D$366,'Analysis Data'!$I$2:$I$366,B12,'Analysis Data'!$C$2:$C$366,"Yes") -> 45012 | L12: =IF(K12=0,0,J12/K12) -> 7.4948014 | M12: =SUMIFS('Analysis Data'!$H$2:$H$366,'Analysis Data'!$I$2:$I$366,B12,'Analysis Data'!$C$2:$C$366,"No") -> 20526 | N12: =_xlfn.MAXIFS('Daily Energy'!$I$2:$I$366,'Analysis Data'!$I$2:$I$366,B12) -> 514 | O12: =SUMIFS('Daily Energy'!$J$2:$J$366,'Analysis Data'!$I$2:$I$366,B12) -> 37 | P12: =AVERAGEIFS('Analysis Data'!$E$2:$E$366,'Analysis Data'!$I$2:$I$366,B12,'Analysis Data'!$C$2:$C$366,"Yes") -> 24.3
A13: =TEXT(B13,"mmm-yy") -> Dec-25 | B13: =EDATE(B12,1) -> 45992 | C13: =COUNTIF('Analysis Data'!$I$2:$I$366,B13) -> 31 | D13: =COUNTIFS('Analysis Data'!$I$2:$I$366,B13,'Analysis Data'!$C$2:$C$366,"Yes") -> 27 | E13: =COUNTIFS('Analysis Data'!$I$2:$I$366,B13,'Analysis Data'!$C$2:$C$366,"No") -> 4 | F13: =SUMIFS('Analysis Data'!$F$2:$F$366,'Analysis Data'!$I$2:$I$366,B13) -> 331060 | G13: =SUMIFS('Analysis Data'!$G$2:$G$366,'Analysis Data'!$I$2:$I$366,B13) -> 48525 | H13: =F13+G13 -> 379585 | I13: =IF(H13=0,0,G13/H13) -> 0.12783698 | J13: =SUMIFS('Analysis Data'!$H$2:$H$366,'Analysis Data'!$I$2:$I$366,B13,'Analysis Data'!$C$2:$C$366,"Yes") -> 362317 | K13: =SUMIFS('Analysis Data'!$D$2:$D$366,'Analysis Data'!$I$2:$I$366,B13,'Analysis Data'!$C$2:$C$366,"Yes") -> 48375 | L13: =IF(K13=0,0,J13/K13) -> 7.4897571 | M13: =SUMIFS('Analysis Data'!$H$2:$H$366,'Analysis Data'!$I$2:$I$366,B13,'Analysis Data'!$C$2:$C$366,"No") -> 17268 | N13: =_xlfn.MAXIFS('Daily Energy'!$I$2:$I$366,'Analysis Data'!$I$2:$I$366,B13) -> 493 | O13: =SUMIFS('Daily Energy'!$J$2:$J$366,'Analysis Data'!$I$2:$I$366,B13) -> 31 | P13: =AVERAGEIFS('Analysis Data'!$E$2:$E$366,'Analysis Data'!$I$2:$I$366,B13,'Analysis Data'!$C$2:$C$366,"Yes") -> 22.359259
A14: =TEXT(B14,"mmm-yy") -> Jan-26 | B14: =EDATE(B13,1) -> 46023 | C14: =COUNTIF('Analysis Data'!$I$2:$I$366,B14) -> 31 | D14: =COUNTIFS('Analysis Data'!$I$2:$I$366,B14,'Analysis Data'!$C$2:$C$366,"Yes") -> 27 | E14: =COUNTIFS('Analysis Data'!$I$2:$I$366,B14,'Analysis Data'!$C$2:$C$366,"No") -> 4 | F14: =SUMIFS('Analysis Data'!$F$2:$F$366,'Analysis Data'!$I$2:$I$366,B14) -> 324131 | G14: =SUMIFS('Analysis Data'!$G$2:$G$366,'Analysis Data'!$I$2:$I$366,B14) -> 48181 | H14: =F14+G14 -> 372312 | I14: =IF(H14=0,0,G14/H14) -> 0.12941028 | J14: =SUMIFS('Analysis Data'!$H$2:$H$366,'Analysis Data'!$I$2:$I$366,B14,'Analysis Data'!$C$2:$C$366,"Yes") -> 355777 | K14: =SUMIFS('Analysis Data'!$D$2:$D$366,'Analysis Data'!$I$2:$I$366,B14,'Analysis Data'!$C$2:$C$366,"Yes") -> 48268 | L14: =IF(K14=0,0,J14/K14) -> 7.3708668 | M14: =SUMIFS('Analysis Data'!$H$2:$H$366,'Analysis Data'!$I$2:$I$366,B14,'Analysis Data'!$C$2:$C$366,"No") -> 16535 | N14: =_xlfn.MAXIFS('Daily Energy'!$I$2:$I$366,'Analysis Data'!$I$2:$I$366,B14) -> 515 | O14: =SUMIFS('Daily Energy'!$J$2:$J$366,'Analysis Data'!$I$2:$I$366,B14) -> 30 | P14: =AVERAGEIFS('Analysis Data'!$E$2:$E$366,'Analysis Data'!$I$2:$I$366,B14,'Analysis Data'!$C$2:$C$366,"Yes") -> 21.011111
A15: =TEXT(B15,"mmm-yy") -> Feb-26 | B15: =EDATE(B14,1) -> 46054 | C15: =COUNTIF('Analysis Data'!$I$2:$I$366,B15) -> 28 | D15: =COUNTIFS('Analysis Data'!$I$2:$I$366,B15,'Analysis Data'!$C$2:$C$366,"Yes") -> 24 | E15: =COUNTIFS('Analysis Data'!$I$2:$I$366,B15,'Analysis Data'!$C$2:$C$366,"No") -> 4 | F15: =SUMIFS('Analysis Data'!$F$2:$F$366,'Analysis Data'!$I$2:$I$366,B15) -> 293591 | G15: =SUMIFS('Analysis Data'!$G$2:$G$366,'Analysis Data'!$I$2:$I$366,B15) -> 45484 | H15: =F15+G15 -> 339075 | I15: =IF(H15=0,0,G15/H15) -> 0.13414141 | J15: =SUMIFS('Analysis Data'!$H$2:$H$366,'Analysis Data'!$I$2:$I$366,B15,'Analysis Data'!$C$2:$C$366,"Yes") -> 323024 | K15: =SUMIFS('Analysis Data'!$D$2:$D$366,'Analysis Data'!$I$2:$I$366,B15,'Analysis Data'!$C$2:$C$366,"Yes") -> 43270 | L15: =IF(K15=0,0,J15/K15) -> 7.4653108 | M15: =SUMIFS('Analysis Data'!$H$2:$H$366,'Analysis Data'!$I$2:$I$366,B15,'Analysis Data'!$C$2:$C$366,"No") -> 16051 | N15: =_xlfn.MAXIFS('Daily Energy'!$I$2:$I$366,'Analysis Data'!$I$2:$I$366,B15) -> 520 | O15: =SUMIFS('Daily Energy'!$J$2:$J$366,'Analysis Data'!$I$2:$I$366,B15) -> 27 | P15: =AVERAGEIFS('Analysis Data'!$E$2:$E$366,'Analysis Data'!$I$2:$I$366,B15,'Analysis Data'!$C$2:$C$366,"Yes") -> 21.408333
A16: =TEXT(B16,"mmm-yy") -> Mar-26 | B16: =EDATE(B15,1) -> 46082 | C16: =COUNTIF('Analysis Data'!$I$2:$I$366,B16) -> 31 | D16: =COUNTIFS('Analysis Data'!$I$2:$I$366,B16,'Analysis Data'!$C$2:$C$366,"Yes") -> 26 | E16: =COUNTIFS('Analysis Data'!$I$2:$I$366,B16,'Analysis Data'!$C$2:$C$366,"No") -> 5 | F16: =SUMIFS('Analysis Data'!$F$2:$F$366,'Analysis Data'!$I$2:$I$366,B16) -> 327886 | G16: =SUMIFS('Analysis Data'!$G$2:$G$366,'Analysis Data'!$I$2:$I$366,B16) -> 52322 | H16: =F16+G16 -> 380208 | I16: =IF(H16=0,0,G16/H16) -> 0.13761415 | J16: =SUMIFS('Analysis Data'!$H$2:$H$366,'Analysis Data'!$I$2:$I$366,B16,'Analysis Data'!$C$2:$C$366,"Yes") -> 359010 | K16: =SUMIFS('Analysis Data'!$D$2:$D$366,'Analysis Data'!$I$2:$I$366,B16,'Analysis Data'!$C$2:$C$366,"Yes") -> 47529 | L16: =IF(K16=0,0,J16/K16) -> 7.5534937 | M16: =SUMIFS('Analysis Data'!$H$2:$H$366,'Analysis Data'!$I$2:$I$366,B16,'Analysis Data'!$C$2:$C$366,"No") -> 21198 | N16: =_xlfn.MAXIFS('Daily Energy'!$I$2:$I$366,'Analysis Data'!$I$2:$I$366,B16) -> 517 | O16: =SUMIFS('Daily Energy'!$J$2:$J$366,'Analysis Data'!$I$2:$I$366,B16) -> 30 | P16: =AVERAGEIFS('Analysis Data'!$E$2:$E$366,'Analysis Data'!$I$2:$I$366,B16,'Analysis Data'!$C$2:$C$366,"Yes") -> 24.061538
A17: Annual | C17: =SUM(C5:C16) -> 365 | D17: =SUM(D5:D16) -> 313 | E17: =SUM(E5:E16) -> 52 | F17: =SUM(F5:F16) -> 4014871 | G17: =SUM(G5:G16) -> 474768 | H17: =SUM(H5:H16) -> 4489639 | I17: =G17/H17 -> 0.10574748 | J17: =SUM(J5:J16) -> 4271630 | K17: =SUM(K5:K16) -> 566026 | L17: =J17/K17 -> 7.5467028 | M17: =SUM(M5:M16) -> 218009 | N17: =MAX(N5:N16) -> 520 | O17: =SUM(O5:O16) -> 364 | P17: =AVERAGEIFS('Analysis Data'!$E$2:$E$366,'Analysis Data'!$C$2:$C$366,"Yes") -> 27.072204
A19: Annual row: sums for volumes; intensity and solar share recomputed from totals; peak demand is the maximum of monthly peaks.

Sheet Analysis Summary
A1: Analysis Summary
A2: Wasteful-day screen and temperature regression — all values calculated by formula from Analysis Data
A3: 1. Wasteful-day screen (non-production days only)
A4: Percentile level | B4: 0.95 | C4: Input — 95th percentile of total daily kWh on non-production days
A5: Screening threshold (kWh) | B5: =PERCENTILE('Analysis Data'!$J$2:$J$366,B4) -> 4687.7 | C5: Agreed methodology: PERCENTILE (inclusive) of non-production-day total kWh
A6: Non-production days | B6: =COUNT('Analysis Data'!$J$2:$J$366) -> 52
A7: Potentially wasteful days | B7: =SUM('Analysis Data'!$L$2:$L$366) -> 3 | C7: Non-production days with total kWh above the threshold. Statistical screen only — not confirmed waste.
A8: Non-production avg daily energy (kWh) | B8: =AVERAGE('Analysis Data'!$J$2:$J$366) -> 4192.4808
A9: Non-production median daily energy (kWh) | B9: =MEDIAN('Analysis Data'!$J$2:$J$366) -> 4230.5
A10: Non-production maximum daily energy (kWh) | B10: =MAX('Analysis Data'!$J$2:$J$366) -> 5179
A11: Production-day avg daily energy (kWh) | B11: =AVERAGE('Analysis Data'!$K$2:$K$366) -> 13647.38
A13: 2. Temperature–energy association (production days, multiple regression)
A14: Observations (production days) | B14: =COUNT('Analysis Data'!$T$2:$T$314) -> 313 | C14: Model: total daily kWh = intercept + b1 × units produced + b2 × average temperature
A15: Temperature coefficient (kWh per °C) | B15: =INDEX(LINEST('Analysis Data'!$T$2:$T$314,'Analysis Data'!$R$2:$S$314,TRUE(),TRUE()),1,1) -> 39.787919 | C15: Holding units produced constant, +1°C is associated with this change in daily kWh
A16: Units-produced coefficient (kWh per unit) | B16: =INDEX(LINEST('Analysis Data'!$T$2:$T$314,'Analysis Data'!$R$2:$S$314,TRUE(),TRUE()),1,2) -> 5.5704279
A17: Intercept (kWh) | B17: =INDEX(LINEST('Analysis Data'!$T$2:$T$314,'Analysis Data'!$R$2:$S$314,TRUE(),TRUE()),1,3) -> 2496.7287
A18: Std. error — temperature coefficient | B18: =INDEX(LINEST('Analysis Data'!$T$2:$T$314,'Analysis Data'!$R$2:$S$314,TRUE(),TRUE()),2,1) -> 5.6685041
A19: Residual degrees of freedom | B19: =INDEX(LINEST('Analysis Data'!$T$2:$T$314,'Analysis Data'!$R$2:$S$314,TRUE(),TRUE()),4,2) -> 310
A20: t critical value (95%, two-tailed) | B20: =TINV(0.05,B19) -> 1.9676459
A21: 95% CI — lower (kWh/°C) | B21: =B15-B20*B18 -> 28.63431
A22: 95% CI — upper (kWh/°C) | B22: =B15+B20*B18 -> 50.941528
A23: R² — multiple regression (units + temperature) | B23: =INDEX(LINEST('Analysis Data'!$T$2:$T$314,'Analysis Data'!$R$2:$S$314,TRUE(),TRUE()),3,1) -> 0.76466563 | C23: The 0.765 R² belongs to this multiple regression only
A24: R² — simple temperature-only regression | B24: =RSQ('Analysis Data'!$T$2:$T$314,'Analysis Data'!$S$2:$S$314) -> 0.072069234 | C24: Temperature alone explains little; shown only for transparency. Used for the scatter trendline.
A25: Slope — simple temperature-only (kWh per °C) | B25: =SLOPE('Analysis Data'!$T$2:$T$314,'Analysis Data'!$S$2:$S$314) -> 55.012064 | C25: Not the headline coefficient; does not control for units produced
A27: 3. Interpretation and limitations
A28: • Temperature–energy relationship is an ASSOCIATION, not proof of causation.
A29: • Wasteful-day flags are a statistical screen of non-production days; they do not establish an operational cause.
A30: • Energy intensity = production-day energy ÷ production-day units (not total energy ÷ units, and not an average of daily ratios).
A31: • Solar share = solar kWh ÷ total kWh (grid + solar), calculated from totals, not by averaging daily percentages.
A32: • Peak demand is a maximum (daily peaks are never summed).
A33: • Dataset is synthetic (per Task Brief) — treat as if real for the exercise.

Sheet Wasteful Days
A1: Potentially Wasteful Days — Statistical Screen
A2: Non-production days with total daily energy above the 95th-percentile threshold. The flag does not confirm operational waste.
A4: Threshold (kWh) | D4: ='Analysis Summary'!B5 -> 4687.7
A5: Flagged days | D5: ='Analysis Summary'!B7 -> 3
A6: Non-production avg (kWh) | D6: ='Analysis Summary'!B8 -> 4192.4808
A8: # | B8: Date | C8: Day | D8: Total energy (kWh) | E8: Grid (kWh) | F8: Solar (kWh) | G8: Peak demand (kW) | H8: Avg temp (°C) | I8: Machine breakdowns | J8: kWh above threshold | K8: % above non-production avg
A9: 1 | B9: =INDEX('Analysis Data'!$A$2:$A$366,MATCH($A9,'Analysis Data'!$M$2:$M$366,0)) -> 45788 | C9: =INDEX('Analysis Data'!$B$2:$B$366,MATCH($A9,'Analysis Data'!$M$2:$M$366,0)) -> Sunday | D9: =INDEX('Analysis Data'!$H$2:$H$366,MATCH($A9,'Analysis Data'!$M$2:$M$366,0)) -> 4917 | E9: =INDEX('Analysis Data'!$F$2:$F$366,MATCH($A9,'Analysis Data'!$M$2:$M$366,0)) -> 3054 | F9: =INDEX('Analysis Data'!$G$2:$G$366,MATCH($A9,'Analysis Data'!$M$2:$M$366,0)) -> 1863 | G9: =INDEX('Daily Energy'!$I$2:$I$366,MATCH($A9,'Analysis Data'!$M$2:$M$366,0)) -> 448 | H9: =INDEX('Analysis Data'!$E$2:$E$366,MATCH($A9,'Analysis Data'!$M$2:$M$366,0)) -> 30.3 | I9: =INDEX('Daily Energy'!$J$2:$J$366,MATCH($A9,'Analysis Data'!$M$2:$M$366,0)) -> 2 | J9: =D9-$D$4 -> 229.3 | K9: =D9/$D$6-1 -> 0.17281397
A10: 2 | B10: =INDEX('Analysis Data'!$A$2:$A$366,MATCH($A10,'Analysis Data'!$M$2:$M$366,0)) -> 45795 | C10: =INDEX('Analysis Data'!$B$2:$B$366,MATCH($A10,'Analysis Data'!$M$2:$M$366,0)) -> Sunday | D10: =INDEX('Analysis Data'!$H$2:$H$366,MATCH($A10,'Analysis Data'!$M$2:$M$366,0)) -> 4790 | E10: =INDEX('Analysis Data'!$F$2:$F$366,MATCH($A10,'Analysis Data'!$M$2:$M$366,0)) -> 3251 | F10: =INDEX('Analysis Data'!$G$2:$G$366,MATCH($A10,'Analysis Data'!$M$2:$M$366,0)) -> 1539 | G10: =INDEX('Daily Energy'!$I$2:$I$366,MATCH($A10,'Analysis Data'!$M$2:$M$366,0)) -> 381 | H10: =INDEX('Analysis Data'!$E$2:$E$366,MATCH($A10,'Analysis Data'!$M$2:$M$366,0)) -> 31.1 | I10: =INDEX('Daily Energy'!$J$2:$J$366,MATCH($A10,'Analysis Data'!$M$2:$M$366,0)) -> 2 | J10: =D10-$D$4 -> 102.3 | K10: =D10/$D$6-1 -> 0.14252164
A11: 3 | B11: =INDEX('Analysis Data'!$A$2:$A$366,MATCH($A11,'Analysis Data'!$M$2:$M$366,0)) -> 45830 | C11: =INDEX('Analysis Data'!$B$2:$B$366,MATCH($A11,'Analysis Data'!$M$2:$M$366,0)) -> Sunday | D11: =INDEX('Analysis Data'!$H$2:$H$366,MATCH($A11,'Analysis Data'!$M$2:$M$366,0)) -> 5179 | E11: =INDEX('Analysis Data'!$F$2:$F$366,MATCH($A11,'Analysis Data'!$M$2:$M$366,0)) -> 4036 | F11: =INDEX('Analysis Data'!$G$2:$G$366,MATCH($A11,'Analysis Data'!$M$2:$M$366,0)) -> 1143 | G11: =INDEX('Daily Energy'!$I$2:$I$366,MATCH($A11,'Analysis Data'!$M$2:$M$366,0)) -> 432 | H11: =INDEX('Analysis Data'!$E$2:$E$366,MATCH($A11,'Analysis Data'!$M$2:$M$366,0)) -> 34.3 | I11: =INDEX('Daily Energy'!$J$2:$J$366,MATCH($A11,'Analysis Data'!$M$2:$M$366,0)) -> 2 | J11: =D11-$D$4 -> 491.3 | K11: =D11/$D$6-1 -> 0.2353068
A13: Method: 95th percentile of total daily kWh across the 52 non-production days; days strictly above the threshold are listed.
A14: Interpretation: unusual non-production consumption warranting review (e.g. equipment left running, maintenance, special activity). The data contains no cause field.
A16: Context — ten highest non-production days
A17: Rank | B17: Date | C17: Day | D17: Total energy (kWh) | E17: Flagged?
A18: 1 | B18: =INDEX('Analysis Data'!$A$2:$A$366,MATCH(D18,'Analysis Data'!$J$2:$J$366,0)) -> 45830 | C18: =INDEX('Analysis Data'!$B$2:$B$366,MATCH(D18,'Analysis Data'!$J$2:$J$366,0)) -> Sunday | D18: =LARGE('Analysis Data'!$J$2:$J$366,A18) -> 5179 | E18: =IF(D18>$D$4,"Potentially wasteful","—") -> Potentially wasteful
